<?xml version="1.0" ?>
<!-- =================================================================================== -->
<!-- |    This document was autogenerated by xacro from /home/ruichao/ipa/denso/trig_ws/src/trig/tests/moveit_configs/gantry_machine_model/codenser/m_2025642_001/m_2025642_001_description/urdf/m_2025642_001.urdf.xacro | -->
<!-- |    EDITING THIS FILE BY HAND IS NOT RECOMMENDED                                 | -->
<!-- =================================================================================== -->
<!-- This URDF was automatically created by SolidWorks to URDF Exporter! Originally created by Stephen Brawner (brawner@gmail.com) 
     Commit Version: 1.6.1-12-ge40d886  Build Version: 1.6.8301.19567
     For more information, please see http://wiki.ros.org/sw_urdf_exporter -->
<robot name="m_2025642_001">
  <link name="m_2025642_001_base_link">
    <inertial>
      <origin rpy="0 0 0" xyz="-2.7746E-05 1.0377E-05 0.11773"/>
      <mass value="2.901"/>
      <inertia ixx="0.021592" ixy="-1.8468E-06" ixz="-9.8111E-08" iyy="0.021626" iyz="1.2451E-07" izz="0.037904"/>
    </inertial>
    <visual>
      <origin rpy="0 0 0" xyz="0 0 0"/>
      <geometry>
        <mesh filename="package://m_2025642_001_description/meshes/base_link.STL"/>
      </geometry>
      <material name="">
        <color rgba="0.75294 0.75294 0.75294 1"/>
      </material>
    </visual>
    <collision>
      <origin rpy="0 0 0" xyz="0 0 0"/>
      <geometry>
        <mesh filename="package://m_2025642_001_description/meshes/base_link.STL"/>
      </geometry>
    </collision>
  </link>
  <link name="m_2025642_001_link_1">
    <inertial>
      <origin rpy="0 0 0" xyz="0.27383 -0.0063157 -0.28956"/>
      <mass value="4.7027"/>
      <inertia ixx="0.25522" ixy="0.013056" ixz="-0.34403" iyy="0.85224" iyz="0.0078809" izz="0.63965"/>
    </inertial>
    <visual>
      <origin rpy="0 0 0" xyz="0 0 0"/>
      <geometry>
        <mesh filename="package://m_2025642_001_description/meshes/link_1.STL"/>
      </geometry>
      <material name="">
        <color rgba="0.75294 0.75294 0.75294 1"/>
      </material>
    </visual>
    <collision>
      <origin rpy="0 0 0" xyz="0 0 0"/>
      <geometry>
        <mesh filename="package://m_2025642_001_description/meshes/link_1.STL"/>
      </geometry>
    </collision>
  </link>
  <joint name="m_2025642_001_joint_1" type="revolute">
    <origin rpy="0 0 0" xyz="0 0 0.57269"/>
    <parent link="m_2025642_001_base_link"/>
    <child link="m_2025642_001_link_1"/>
    <axis xyz="0 0 1"/>
    <limit effort="0.1" lower="-1.0" upper="1.0" velocity="0.1"/>
  </joint>
  <link name="m_2025642_001_link_2">
    <inertial>
      <origin rpy="0 0 0" xyz="-0.075618 0.013344 -0.40578"/>
      <mass value="4.7027"/>
      <inertia ixx="0.25522" ixy="0.013056" ixz="-0.34403" iyy="0.85224" iyz="0.0078809" izz="0.63965"/>
    </inertial>
    <visual>
      <origin rpy="0 0 0" xyz="0 0 0"/>
      <geometry>
        <mesh filename="package://m_2025642_001_description/meshes/link_2.STL"/>
      </geometry>
      <material name="">
        <color rgba="0.75294 0.75294 0.75294 1"/>
      </material>
    </visual>
    <collision>
      <origin rpy="0 0 0" xyz="0 0 0"/>
      <geometry>
        <mesh filename="package://m_2025642_001_description/meshes/link_2.STL"/>
      </geometry>
    </collision>
  </link>
  <joint name="m_2025642_001_joint_2" type="revolute">
    <origin rpy="0 0 0" xyz="0.34945 -0.019659 0.11622"/>
    <parent link="m_2025642_001_link_1"/>
    <child link="m_2025642_001_link_2"/>
    <axis xyz="0 0 1"/>
    <limit effort="0.1" lower="-1.0" upper="1.0" velocity="0.1"/>
  </joint>
  <link name="m_2025642_001_link_3">
    <inertial>
      <origin rpy="0 0 0" xyz="-0.42562 0.013344 -0.39507"/>
      <mass value="4.7027"/>
      <inertia ixx="0.25522" ixy="0.013056" ixz="-0.34403" iyy="0.85224" iyz="0.0078809" izz="0.63965"/>
    </inertial>
    <visual>
      <origin rpy="0 0 0" xyz="0 0 0"/>
      <geometry>
        <mesh filename="package://m_2025642_001_description/meshes/link_3.STL"/>
      </geometry>
      <material name="">
        <color rgba="0.75294 0.75294 0.75294 1"/>
      </material>
    </visual>
    <collision>
      <origin rpy="0 0 0" xyz="0 0 0"/>
      <geometry>
        <mesh filename="package://m_2025642_001_description/meshes/link_3.STL"/>
      </geometry>
    </collision>
  </link>
  <joint name="m_2025642_001_joint_3" type="prismatic">
    <origin rpy="0 0 0" xyz="0.35 0 -0.01071"/>
    <parent link="m_2025642_001_link_2"/>
    <child link="m_2025642_001_link_3"/>
    <axis xyz="0 0 1"/>
    <limit effort="0.1" lower="-0.1" upper="0.05" velocity="0.1"/>
  </joint>
  <link name="m_2025642_001_link_4">
    <inertial>
      <origin rpy="0 0 0" xyz="0.018596 0.0019918 0.018216"/>
      <mass value="1.0033"/>
      <inertia ixx="0.00065498" ixy="2.4675E-06" ixz="-1.1852E-05" iyy="0.0040429" iyz="4.0062E-06" izz="0.0045133"/>
    </inertial>
    <visual>
      <origin rpy="0 0 0" xyz="0 0 0"/>
      <geometry>
        <mesh filename="package://m_2025642_001_description/meshes/link_4.STL"/>
      </geometry>
      <material name="">
        <color rgba="0.75294 0.75294 0.75294 1"/>
      </material>
    </visual>
    <collision>
      <origin rpy="0 0 0" xyz="0 0 0"/>
      <geometry>
        <mesh filename="package://m_2025642_001_description/meshes/link_4.STL"/>
      </geometry>
    </collision>
  </link>
  <joint name="m_2025642_001_joint_4" type="revolute">
    <origin rpy="0 0 0" xyz="0 0.0020727 -0.155"/>
    <parent link="m_2025642_001_link_3"/>
    <child link="m_2025642_001_link_4"/>
    <axis xyz="0 0 1"/>
    <limit effort="0.1" lower="-0.2" upper="0.2" velocity="0.1"/>
  </joint>
  <link name="m_2025642_001_gripper_right_link">
    <inertial>
      <origin rpy="0 0 0" xyz="-0.042744 0.0023468 0.042891"/>
      <mass value="0.43089"/>
      <inertia ixx="0.00044467" ixy="-5.9136E-06" ixz="5.7977E-05" iyy="0.00073715" iyz="-1.5119E-06" izz="0.00087355"/>
    </inertial>
    <visual>
      <origin rpy="0 0 0" xyz="0 0 0"/>
      <geometry>
        <mesh filename="package://m_2025642_001_description/meshes/gripper_right_link.STL"/>
      </geometry>
      <material name="">
        <color rgba="0.75294 0.75294 0.75294 1"/>
      </material>
    </visual>
    <collision>
      <origin rpy="0 0 0" xyz="0 0 0"/>
      <geometry>
        <mesh filename="package://m_2025642_001_description/meshes/gripper_right_link.STL"/>
      </geometry>
    </collision>
  </link>
  <joint name="m_2025642_001_gripper_right_joint" type="prismatic">
    <origin rpy="0 0 0" xyz="0.19 -0.0020727 0.0014243"/>
    <parent link="m_2025642_001_link_4"/>
    <child link="m_2025642_001_gripper_right_link"/>
    <axis xyz="1 0 0"/>
    <limit effort="0.1" lower="0" upper="0.1" velocity="0.1"/>
  </joint>
  <link name="m_2025642_001_gripper_left_link">
    <inertial>
      <origin rpy="0 0 0" xyz="0.007756 0.0016325 0.025599"/>
      <mass value="0.36755"/>
      <inertia ixx="0.00075935" ixy="1.125E-08" ixz="-2.7795E-05" iyy="0.00045486" iyz="5.4225E-08" izz="0.00079529"/>
    </inertial>
    <visual>
      <origin rpy="0 0 0" xyz="0 0 0"/>
      <geometry>
        <mesh filename="package://m_2025642_001_description/meshes/gripper_left_link.STL"/>
      </geometry>
      <material name="">
        <color rgba="0.75294 0.75294 0.75294 1"/>
      </material>
    </visual>
    <collision>
      <origin rpy="0 0 0" xyz="0 0 0"/>
      <geometry>
        <mesh filename="package://m_2025642_001_description/meshes/gripper_left_link.STL"/>
      </geometry>
    </collision>
  </link>
  <joint name="m_2025642_001_gripper_left_joint" type="prismatic">
    <origin rpy="0 0 0" xyz="-0.156 -0.0020727 0.0014243"/>
    <parent link="m_2025642_001_link_4"/>
    <child link="m_2025642_001_gripper_left_link"/>
    <axis xyz="-1 0 0"/>
    <limit effort="0.1" lower="0" upper="0.06" velocity="0.1"/>
  </joint>
</robot>
