<?xml version="1.0" ?>
<!-- =================================================================================== -->
<!-- |    This document was autogenerated by xacro from /home/ipa-hsd/projects/denso/ros2_ws/src/component_models/codenser/m_4730788_001/m_4730788_001_description/urdf/m_4730788_001.urdf.xacro | -->
<!-- |    EDITING THIS FILE BY HAND IS NOT RECOMMENDED                                 | -->
<!-- =================================================================================== -->
<!-- This URDF was automatically created by SolidWorks to URDF Exporter! Originally created by Stephen Brawner (brawner@gmail.com) 
     Commit Version: 1.6.1-12-ge40d886  Build Version: 1.6.8301.19567
     For more information, please see http://wiki.ros.org/sw_urdf_exporter -->
<robot name="m_4730788_001">
  <link name="m_4730788_001_base_link">
    <inertial>
      <origin rpy="0 0 0" xyz="-0.0079588 0.53745 0.29257"/>
      <mass value="25.945"/>
      <inertia ixx="3.1047" ixy="7.4183E-05" ixz="-0.00021729" iyy="0.061286" iyz="0.0088416" izz="3.1103"/>
    </inertial>
    <visual>
      <origin rpy="0 0 0" xyz="0 0 0"/>
      <geometry>
        <mesh filename="package://m_4730788_001_description/meshes/base_link.STL"/>
      </geometry>
      <material name="">
        <color rgba="0.75294 0.75294 0.75294 1"/>
      </material>
    </visual>
    <collision>
      <origin rpy="0 0 0" xyz="0 0 0"/>
      <geometry>
        <mesh filename="package://m_4730788_001_description/meshes/base_link.STL"/>
      </geometry>
    </collision>
  </link>
  <link name="m_4730788_001_link_1">
    <inertial>
      <origin rpy="0 0 0" xyz="0.035968 0.27493 0.22182"/>
      <mass value="5.6095"/>
      <inertia ixx="0.069776" ixy="-4.5144E-06" ixz="-0.00039418" iyy="0.068863" iyz="-3.9361E-06" izz="0.0062752"/>
    </inertial>
    <visual>
      <origin rpy="0 0 0" xyz="0 0 0"/>
      <geometry>
        <mesh filename="package://m_4730788_001_description/meshes/link_1.STL"/>
      </geometry>
      <material name="">
        <color rgba="0.75294 0.75294 0.75294 1"/>
      </material>
    </visual>
    <collision>
      <origin rpy="0 0 0" xyz="0 0 0"/>
      <geometry>
        <mesh filename="package://m_4730788_001_description/meshes/link_1.STL"/>
      </geometry>
    </collision>
  </link>
  <joint name="m_4730788_001_joint_1" type="prismatic">
    <origin rpy="0 0 0" xyz="0 -0.0041461 0.37535"/>
    <parent link="m_4730788_001_base_link"/>
    <child link="m_4730788_001_link_1"/>
    <axis xyz="0 1 0"/>
    <limit effort="0.1" lower="0" upper="1.0" velocity="0.1"/>
  </joint>
  <link name="m_4730788_001_link_2">
    <inertial>
      <origin rpy="0 0 0" xyz="0.1819 1.4438E-05 -0.12956"/>
      <mass value="1.8798"/>
      <inertia ixx="0.0025187" ixy="-1.2207E-05" ixz="8.5334E-07" iyy="0.0027656" iyz="1.0645E-07" izz="0.0012183"/>
    </inertial>
    <visual>
      <origin rpy="0 0 0" xyz="0 0 0"/>
      <geometry>
        <mesh filename="package://m_4730788_001_description/meshes/link_2.STL"/>
      </geometry>
      <material name="">
        <color rgba="0.75294 0.75294 0.75294 1"/>
      </material>
    </visual>
    <collision>
      <origin rpy="0 0 0" xyz="0 0 0"/>
      <geometry>
        <mesh filename="package://m_4730788_001_description/meshes/link_2.STL"/>
      </geometry>
    </collision>
  </link>
  <joint name="m_4730788_001_joint_2" type="prismatic">
    <origin rpy="0 0 0" xyz="0.074922 0.27494 0.46365"/>
    <parent link="m_4730788_001_link_1"/>
    <child link="m_4730788_001_link_2"/>
    <axis xyz="0 0 1"/>
    <limit effort="0.1" lower="-0.2" upper="0.25" velocity="0.1"/>
  </joint>
</robot>
