<?xml version="1.0" ?>
<!-- =================================================================================== -->
<!-- |    This document was autogenerated by xacro from ./src/component_models/machines/codenser_double/codenser_double_description/urdf/codenser_double.urdf.xacro | -->
<!-- |    EDITING THIS FILE BY HAND IS NOT RECOMMENDED                                 | -->
<!-- =================================================================================== -->
<!-- This URDF was automatically created by SolidWorks to URDF Exporter! Originally created by Stephen Brawner (brawner@gmail.com) 
     Commit Version: 1.6.1-12-ge40d886  Build Version: 1.6.8301.19567
     For more information, please see http://wiki.ros.org/sw_urdf_exporter -->
<robot name="codenser_double">
  <link name="c_203_robot_arm_base_link">
    <inertial>
      <origin rpy="0 0 0" xyz="-2.7746E-05 1.0377E-05 0.11773"/>
      <mass value="2.901"/>
      <inertia ixx="0.021592" ixy="-1.8468E-06" ixz="-9.8111E-08" iyy="0.021626" iyz="1.2451E-07" izz="0.037904"/>
    </inertial>
    <visual>
      <origin rpy="0 0 0" xyz="0 0 0"/>
      <geometry>
        <mesh filename="package://m_2025642_001_description/meshes/base_link.STL"/>
      </geometry>
      <material name="">
        <color rgba="0.75294 0.75294 0.75294 1"/>
      </material>
    </visual>
    <collision>
      <origin rpy="0 0 0" xyz="0 0 0"/>
      <geometry>
        <mesh filename="package://m_2025642_001_description/meshes/base_link.STL"/>
      </geometry>
    </collision>
  </link>
  <link name="c_203_robot_arm_link_1">
    <inertial>
      <origin rpy="0 0 0" xyz="0.27383 -0.0063157 -0.28956"/>
      <mass value="4.7027"/>
      <inertia ixx="0.25522" ixy="0.013056" ixz="-0.34403" iyy="0.85224" iyz="0.0078809" izz="0.63965"/>
    </inertial>
    <visual>
      <origin rpy="0 0 0" xyz="0 0 0"/>
      <geometry>
        <mesh filename="package://m_2025642_001_description/meshes/link_1.STL"/>
      </geometry>
      <material name="">
        <color rgba="0.75294 0.75294 0.75294 1"/>
      </material>
    </visual>
    <collision>
      <origin rpy="0 0 0" xyz="0 0 0"/>
      <geometry>
        <mesh filename="package://m_2025642_001_description/meshes/link_1.STL"/>
      </geometry>
    </collision>
  </link>
  <joint name="c_203_robot_arm_joint_1" type="revolute">
    <origin rpy="0 0 0" xyz="0 0 0.57269"/>
    <parent link="c_203_robot_arm_base_link"/>
    <child link="c_203_robot_arm_link_1"/>
    <axis xyz="0 0 1"/>
    <limit effort="0.1" lower="-1.0" upper="1.0" velocity="0.1"/>
  </joint>
  <link name="c_203_robot_arm_link_2">
    <inertial>
      <origin rpy="0 0 0" xyz="-0.075618 0.013344 -0.40578"/>
      <mass value="4.7027"/>
      <inertia ixx="0.25522" ixy="0.013056" ixz="-0.34403" iyy="0.85224" iyz="0.0078809" izz="0.63965"/>
    </inertial>
    <visual>
      <origin rpy="0 0 0" xyz="0 0 0"/>
      <geometry>
        <mesh filename="package://m_2025642_001_description/meshes/link_2.STL"/>
      </geometry>
      <material name="">
        <color rgba="0.75294 0.75294 0.75294 1"/>
      </material>
    </visual>
    <collision>
      <origin rpy="0 0 0" xyz="0 0 0"/>
      <geometry>
        <mesh filename="package://m_2025642_001_description/meshes/link_2.STL"/>
      </geometry>
    </collision>
  </link>
  <joint name="c_203_robot_arm_joint_2" type="revolute">
    <origin rpy="0 0 0" xyz="0.34945 -0.019659 0.11622"/>
    <parent link="c_203_robot_arm_link_1"/>
    <child link="c_203_robot_arm_link_2"/>
    <axis xyz="0 0 1"/>
    <limit effort="0.1" lower="-1.0" upper="1.0" velocity="0.1"/>
  </joint>
  <link name="c_203_robot_arm_link_3">
    <inertial>
      <origin rpy="0 0 0" xyz="-0.42562 0.013344 -0.39507"/>
      <mass value="4.7027"/>
      <inertia ixx="0.25522" ixy="0.013056" ixz="-0.34403" iyy="0.85224" iyz="0.0078809" izz="0.63965"/>
    </inertial>
    <visual>
      <origin rpy="0 0 0" xyz="0 0 0"/>
      <geometry>
        <mesh filename="package://m_2025642_001_description/meshes/link_3.STL"/>
      </geometry>
      <material name="">
        <color rgba="0.75294 0.75294 0.75294 1"/>
      </material>
    </visual>
    <collision>
      <origin rpy="0 0 0" xyz="0 0 0"/>
      <geometry>
        <mesh filename="package://m_2025642_001_description/meshes/link_3.STL"/>
      </geometry>
    </collision>
  </link>
  <joint name="c_203_robot_arm_joint_3" type="prismatic">
    <origin rpy="0 0 0" xyz="0.35 0 -0.01071"/>
    <parent link="c_203_robot_arm_link_2"/>
    <child link="c_203_robot_arm_link_3"/>
    <axis xyz="0 0 1"/>
    <limit effort="0.1" lower="-0.1" upper="0.05" velocity="0.1"/>
  </joint>
  <link name="c_203_robot_arm_link_4">
    <inertial>
      <origin rpy="0 0 0" xyz="0.018596 0.0019918 0.018216"/>
      <mass value="1.0033"/>
      <inertia ixx="0.00065498" ixy="2.4675E-06" ixz="-1.1852E-05" iyy="0.0040429" iyz="4.0062E-06" izz="0.0045133"/>
    </inertial>
    <visual>
      <origin rpy="0 0 0" xyz="0 0 0"/>
      <geometry>
        <mesh filename="package://m_2025642_001_description/meshes/link_4.STL"/>
      </geometry>
      <material name="">
        <color rgba="0.75294 0.75294 0.75294 1"/>
      </material>
    </visual>
    <collision>
      <origin rpy="0 0 0" xyz="0 0 0"/>
      <geometry>
        <mesh filename="package://m_2025642_001_description/meshes/link_4.STL"/>
      </geometry>
    </collision>
  </link>
  <joint name="c_203_robot_arm_joint_4" type="revolute">
    <origin rpy="0 0 0" xyz="0 0.0020727 -0.155"/>
    <parent link="c_203_robot_arm_link_3"/>
    <child link="c_203_robot_arm_link_4"/>
    <axis xyz="0 0 1"/>
    <limit effort="0.1" lower="-0.2" upper="0.2" velocity="0.1"/>
  </joint>
  <link name="c_203_robot_arm_gripper_right_link">
    <inertial>
      <origin rpy="0 0 0" xyz="-0.042744 0.0023468 0.042891"/>
      <mass value="0.43089"/>
      <inertia ixx="0.00044467" ixy="-5.9136E-06" ixz="5.7977E-05" iyy="0.00073715" iyz="-1.5119E-06" izz="0.00087355"/>
    </inertial>
    <visual>
      <origin rpy="0 0 0" xyz="0 0 0"/>
      <geometry>
        <mesh filename="package://m_2025642_001_description/meshes/gripper_right_link.STL"/>
      </geometry>
      <material name="">
        <color rgba="0.75294 0.75294 0.75294 1"/>
      </material>
    </visual>
    <collision>
      <origin rpy="0 0 0" xyz="0 0 0"/>
      <geometry>
        <mesh filename="package://m_2025642_001_description/meshes/gripper_right_link.STL"/>
      </geometry>
    </collision>
  </link>
  <joint name="c_203_robot_arm_gripper_right_joint" type="prismatic">
    <origin rpy="0 0 0" xyz="0.19 -0.0020727 0.0014243"/>
    <parent link="c_203_robot_arm_link_4"/>
    <child link="c_203_robot_arm_gripper_right_link"/>
    <axis xyz="1 0 0"/>
    <limit effort="0.1" lower="0" upper="0.1" velocity="0.1"/>
  </joint>
  <link name="c_203_robot_arm_gripper_left_link">
    <inertial>
      <origin rpy="0 0 0" xyz="0.007756 0.0016325 0.025599"/>
      <mass value="0.36755"/>
      <inertia ixx="0.00075935" ixy="1.125E-08" ixz="-2.7795E-05" iyy="0.00045486" iyz="5.4225E-08" izz="0.00079529"/>
    </inertial>
    <visual>
      <origin rpy="0 0 0" xyz="0 0 0"/>
      <geometry>
        <mesh filename="package://m_2025642_001_description/meshes/gripper_left_link.STL"/>
      </geometry>
      <material name="">
        <color rgba="0.75294 0.75294 0.75294 1"/>
      </material>
    </visual>
    <collision>
      <origin rpy="0 0 0" xyz="0 0 0"/>
      <geometry>
        <mesh filename="package://m_2025642_001_description/meshes/gripper_left_link.STL"/>
      </geometry>
    </collision>
  </link>
  <joint name="c_203_robot_arm_gripper_left_joint" type="prismatic">
    <origin rpy="0 0 0" xyz="-0.156 -0.0020727 0.0014243"/>
    <parent link="c_203_robot_arm_link_4"/>
    <child link="c_203_robot_arm_gripper_left_link"/>
    <axis xyz="-1 0 0"/>
    <limit effort="0.1" lower="0" upper="0.06" velocity="0.1"/>
  </joint>
  <link name="c_204_pick_place_system_base_link">
    <inertial>
      <origin rpy="0 0 0" xyz="0.58983 0.63355 0.96408"/>
      <mass value="56.671"/>
      <inertia ixx="5.0862" ixy="0.096549" ixz="0.011489" iyy="11.551" iyz="0.00029138" izz="15.131"/>
    </inertial>
    <visual>
      <origin rpy="0 0 0" xyz="0 0 0"/>
      <geometry>
        <mesh filename="package://m_2025643_001_description/meshes/base_link.STL"/>
      </geometry>
      <material name="">
        <color rgba="0.75294 0.75294 0.75294 1"/>
      </material>
    </visual>
    <collision>
      <origin rpy="0 0 0" xyz="0 0 0"/>
      <geometry>
        <mesh filename="package://m_2025643_001_description/meshes/base_link.STL"/>
      </geometry>
    </collision>
  </link>
  <link name="c_204_pick_place_system_link_1">
    <inertial>
      <origin rpy="0 0 0" xyz="0.11461 -0.023751 -0.20534"/>
      <mass value="17.887"/>
      <inertia ixx="0.85265" ixy="0.0020243" ixz="0.0034461" iyy="0.42068" iyz="-0.00010302" izz="0.47399"/>
    </inertial>
    <visual>
      <origin rpy="0 0 0" xyz="0 0 0"/>
      <geometry>
        <mesh filename="package://m_2025643_001_description/meshes/link_1.STL"/>
      </geometry>
      <material name="">
        <color rgba="0.75294 0.75294 0.75294 1"/>
      </material>
    </visual>
    <collision>
      <origin rpy="0 0 0" xyz="0 0 0"/>
      <geometry>
        <mesh filename="package://m_2025643_001_description/meshes/link_1.STL"/>
      </geometry>
    </collision>
  </link>
  <joint name="c_204_pick_place_system_joint_1" type="prismatic">
    <origin rpy="0 0 0" xyz="-0.37671 0.676 1.2315"/>
    <parent link="c_204_pick_place_system_base_link"/>
    <child link="c_204_pick_place_system_link_1"/>
    <axis xyz="1 0 0"/>
    <limit effort="0.1" lower="0" upper="1.5" velocity="0.1"/>
  </joint>
  <link name="c_204_pick_place_system_link_2">
    <inertial>
      <origin rpy="0 0 0" xyz="0.070659 -0.031425 0.0021627"/>
      <mass value="8.1181"/>
      <inertia ixx="0.43894" ixy="0.0013519" ixz="0.00017093" iyy="0.045982" iyz="-0.0024625" izz="0.45094"/>
    </inertial>
    <visual>
      <origin rpy="0 0 0" xyz="0 0 0"/>
      <geometry>
        <mesh filename="package://m_2025643_001_description/meshes/link_2.STL"/>
      </geometry>
      <material name="">
        <color rgba="0.75294 0.75294 0.75294 1"/>
      </material>
    </visual>
    <collision>
      <origin rpy="0 0 0" xyz="0 0 0"/>
      <geometry>
        <mesh filename="package://m_2025643_001_description/meshes/link_2.STL"/>
      </geometry>
    </collision>
  </link>
  <joint name="c_204_pick_place_system_joint_2" type="prismatic">
    <origin rpy="0 0 0" xyz="0.20285 -0.084066 -0.62709"/>
    <parent link="c_204_pick_place_system_link_1"/>
    <child link="c_204_pick_place_system_link_2"/>
    <axis xyz="0 0 1"/>
    <limit effort="0.1" lower="0" upper="0.5" velocity="0.1"/>
  </joint>
  <link name="c_204_pick_place_system_gripper_left_link">
    <inertial>
      <origin rpy="0 0 0" xyz="-0.016946 -0.019226 -0.088431"/>
      <mass value="1.0465"/>
      <inertia ixx="0.0009527" ixy="-0.00010594" ixz="0.00013512" iyy="0.0010535" iyz="0.00011099" izz="0.001289"/>
    </inertial>
    <visual>
      <origin rpy="0 0 0" xyz="0 0 0"/>
      <geometry>
        <mesh filename="package://m_2025643_001_description/meshes/gripper_left_link.STL"/>
      </geometry>
      <material name="">
        <color rgba="0.75294 0.75294 0.75294 1"/>
      </material>
    </visual>
    <collision>
      <origin rpy="0 0 0" xyz="0 0 0"/>
      <geometry>
        <mesh filename="package://m_2025643_001_description/meshes/gripper_left_link.STL"/>
      </geometry>
    </collision>
  </link>
  <joint name="c_204_pick_place_system_gripper_left_joint" type="prismatic">
    <origin rpy="0 0 0" xyz="0.286 -0.37124 -0.046329"/>
    <parent link="c_204_pick_place_system_link_2"/>
    <child link="c_204_pick_place_system_gripper_left_link"/>
    <axis xyz="0 1 0"/>
    <limit effort="0.1" lower="0" upper="0.1" velocity="0.1"/>
  </joint>
  <link name="c_204_pick_place_system_finger_left_link">
    <inertial>
      <origin rpy="0 0 0" xyz="0.0044985 0.062888 -0.006434"/>
      <mass value="0.38585"/>
      <inertia ixx="0.00020691" ixy="2.0797E-07" ixz="-4.5948E-07" iyy="0.00034559" iyz="-3.5191E-07" izz="0.00038383"/>
    </inertial>
    <visual>
      <origin rpy="0 0 0" xyz="0 0 0"/>
      <geometry>
        <mesh filename="package://m_2025643_001_description/meshes/finger_left_link.STL"/>
      </geometry>
      <material name="">
        <color rgba="0.75294 0.75294 0.75294 1"/>
      </material>
    </visual>
    <collision>
      <origin rpy="0 0 0" xyz="0 0 0"/>
      <geometry>
        <mesh filename="package://m_2025643_001_description/meshes/finger_left_link.STL"/>
      </geometry>
    </collision>
  </link>
  <joint name="c_204_pick_place_system_finger_left_joint" type="revolute">
    <origin rpy="0 0 0" xyz="0 0.047 -0.148"/>
    <parent link="c_204_pick_place_system_gripper_left_link"/>
    <child link="c_204_pick_place_system_finger_left_link"/>
    <axis xyz="0 1 0"/>
    <limit effort="0.1" lower="-0.5" upper="0.5" velocity="0.1"/>
  </joint>
  <link name="c_208_workpiece_lifter_base_link">
    <inertial>
      <origin rpy="0 0 0" xyz="0.23397 0.00029888 0.15629"/>
      <mass value="5.7833"/>
      <inertia ixx="0.029824" ixy="0.0001163" ixz="-2.0315E-05" iyy="0.044642" iyz="3.2398E-05" izz="0.057924"/>
    </inertial>
    <visual>
      <origin rpy="0 0 0" xyz="0 0 0"/>
      <geometry>
        <mesh filename="package://m_2063306_000_description/meshes/base_link.STL"/>
      </geometry>
      <material name="">
        <color rgba="0.75294 0.75294 0.75294 1"/>
      </material>
    </visual>
    <collision>
      <origin rpy="0 0 0" xyz="0 0 0"/>
      <geometry>
        <mesh filename="package://m_2063306_000_description/meshes/base_link.STL"/>
      </geometry>
    </collision>
  </link>
  <link name="c_208_workpiece_lifter_link_1">
    <inertial>
      <origin rpy="0 0 0" xyz="-0.0010188 0.00075539 0.25483"/>
      <mass value="4.9135"/>
      <inertia ixx="0.023378" ixy="-0.00023389" ixz="5.6233E-06" iyy="0.026512" iyz="-1.1668E-05" izz="0.044967"/>
    </inertial>
    <visual>
      <origin rpy="0 0 0" xyz="0 0 0"/>
      <geometry>
        <mesh filename="package://m_2063306_000_description/meshes/link_1.STL"/>
      </geometry>
      <material name="">
        <color rgba="0.75294 0.75294 0.75294 1"/>
      </material>
    </visual>
    <collision>
      <origin rpy="0 0 0" xyz="0 0 0"/>
      <geometry>
        <mesh filename="package://m_2063306_000_description/meshes/link_1.STL"/>
      </geometry>
    </collision>
  </link>
  <joint name="c_208_workpiece_lifter_joint_1" type="prismatic">
    <origin rpy="0 0 0" xyz="0.2845 0 0.127"/>
    <parent link="c_208_workpiece_lifter_base_link"/>
    <child link="c_208_workpiece_lifter_link_1"/>
    <axis xyz="0 0 1"/>
    <limit effort="0.1" lower="0" upper="0.1" velocity="0.1"/>
  </joint>
  <link name="c_205_workpiece_holder_base_link">
    <inertial>
      <origin rpy="0 0 0" xyz="-0.00033345 0.00023906 0.25293"/>
      <mass value="2.0735"/>
      <inertia ixx="0.0091049" ixy="-7.0561E-07" ixz="-1.5489E-07" iyy="0.0061399" iyz="4.7348E-08" izz="0.012288"/>
    </inertial>
    <visual>
      <origin rpy="0 0 0" xyz="0 0 0"/>
      <geometry>
        <mesh filename="package://m_2154940_001_description/meshes/base_link.STL"/>
      </geometry>
      <material name="">
        <color rgba="0.75294 0.75294 0.75294 1"/>
      </material>
    </visual>
    <collision>
      <origin rpy="0 0 0" xyz="0 0 0"/>
      <geometry>
        <mesh filename="package://m_2154940_001_description/meshes/base_link.STL"/>
      </geometry>
    </collision>
  </link>
  <link name="c_206_height_check_system_base_link">
    <inertial>
      <origin rpy="0 0 0" xyz="-0.0079588 0.53745 0.29257"/>
      <mass value="25.945"/>
      <inertia ixx="3.1047" ixy="7.4183E-05" ixz="-0.00021729" iyy="0.061286" iyz="0.0088416" izz="3.1103"/>
    </inertial>
    <visual>
      <origin rpy="0 0 0" xyz="0 0 0"/>
      <geometry>
        <mesh filename="package://m_4730788_001_description/meshes/base_link.STL"/>
      </geometry>
      <material name="">
        <color rgba="0.75294 0.75294 0.75294 1"/>
      </material>
    </visual>
    <collision>
      <origin rpy="0 0 0" xyz="0 0 0"/>
      <geometry>
        <mesh filename="package://m_4730788_001_description/meshes/base_link.STL"/>
      </geometry>
    </collision>
  </link>
  <link name="c_206_height_check_system_link_1">
    <inertial>
      <origin rpy="0 0 0" xyz="0.035968 0.27493 0.22182"/>
      <mass value="5.6095"/>
      <inertia ixx="0.069776" ixy="-4.5144E-06" ixz="-0.00039418" iyy="0.068863" iyz="-3.9361E-06" izz="0.0062752"/>
    </inertial>
    <visual>
      <origin rpy="0 0 0" xyz="0 0 0"/>
      <geometry>
        <mesh filename="package://m_4730788_001_description/meshes/link_1.STL"/>
      </geometry>
      <material name="">
        <color rgba="0.75294 0.75294 0.75294 1"/>
      </material>
    </visual>
    <collision>
      <origin rpy="0 0 0" xyz="0 0 0"/>
      <geometry>
        <mesh filename="package://m_4730788_001_description/meshes/link_1.STL"/>
      </geometry>
    </collision>
  </link>
  <joint name="c_206_height_check_system_joint_1" type="prismatic">
    <origin rpy="0 0 0" xyz="0 -0.0041461 0.37535"/>
    <parent link="c_206_height_check_system_base_link"/>
    <child link="c_206_height_check_system_link_1"/>
    <axis xyz="0 1 0"/>
    <limit effort="0.1" lower="0" upper="1.0" velocity="0.1"/>
  </joint>
  <link name="c_206_height_check_system_link_2">
    <inertial>
      <origin rpy="0 0 0" xyz="0.1819 1.4438E-05 -0.12956"/>
      <mass value="1.8798"/>
      <inertia ixx="0.0025187" ixy="-1.2207E-05" ixz="8.5334E-07" iyy="0.0027656" iyz="1.0645E-07" izz="0.0012183"/>
    </inertial>
    <visual>
      <origin rpy="0 0 0" xyz="0 0 0"/>
      <geometry>
        <mesh filename="package://m_4730788_001_description/meshes/link_2.STL"/>
      </geometry>
      <material name="">
        <color rgba="0.75294 0.75294 0.75294 1"/>
      </material>
    </visual>
    <collision>
      <origin rpy="0 0 0" xyz="0 0 0"/>
      <geometry>
        <mesh filename="package://m_4730788_001_description/meshes/link_2.STL"/>
      </geometry>
    </collision>
  </link>
  <joint name="c_206_height_check_system_joint_2" type="prismatic">
    <origin rpy="0 0 0" xyz="0.074922 0.27494 0.46365"/>
    <parent link="c_206_height_check_system_link_1"/>
    <child link="c_206_height_check_system_link_2"/>
    <axis xyz="0 0 1"/>
    <limit effort="0.1" lower="-0.2" upper="0.25" velocity="0.1"/>
  </joint>
  <link name="c_207_workpiece_feeder_base_link">
    <inertial>
      <origin rpy="0 0 0" xyz="-0.14164 -0.59781 -0.44321"/>
      <mass value="21.523"/>
      <inertia ixx="0.088184" ixy="3.5897E-05" ixz="-1.1803E-05" iyy="2.7101" iyz="-0.0006684" izz="2.6633"/>
    </inertial>
    <visual>
      <origin rpy="0 0 0" xyz="0 0 0"/>
      <geometry>
        <mesh filename="package://m_5326927_001_description/meshes/base_link.STL"/>
      </geometry>
      <material name="">
        <color rgba="0.8549 0.74118 0.91765 1"/>
      </material>
    </visual>
    <collision>
      <origin rpy="0 0 0" xyz="0 0 0"/>
      <geometry>
        <mesh filename="package://m_5326927_001_description/meshes/base_link.STL"/>
      </geometry>
    </collision>
  </link>
  <link name="c_207_workpiece_feeder_zone_link">
    <visual>
      <origin rpy="0 0 0" xyz="0 0 0"/>
      <geometry>
        <box size="0.4 0.65 0.1"/>
      </geometry>
    </visual>
    <collision>
      <origin rpy="0 0 0" xyz="0 0 0"/>
      <geometry>
        <box size="0.4 0.65 0.1"/>
      </geometry>
    </collision>
  </link>
  <joint name="c_207_workpiece_feeder_joint_1" type="prismatic">
    <origin rpy="0 0 0" xyz="0 0 0.6"/>
    <parent link="c_207_workpiece_feeder_base_link"/>
    <child link="c_207_workpiece_feeder_zone_link"/>
    <axis xyz="0 1 0"/>
    <limit effort="0.1" lower="0" upper="1.5" velocity="0.1"/>
  </joint>
  <link name="c_303_robot_arm_2_base_link">
    <inertial>
      <origin rpy="0 0 0" xyz="-2.7746E-05 1.0377E-05 0.11773"/>
      <mass value="2.901"/>
      <inertia ixx="0.021592" ixy="-1.8468E-06" ixz="-9.8111E-08" iyy="0.021626" iyz="1.2451E-07" izz="0.037904"/>
    </inertial>
    <visual>
      <origin rpy="0 0 0" xyz="0 0 0"/>
      <geometry>
        <mesh filename="package://m_2025642_001_description/meshes/base_link.STL"/>
      </geometry>
      <material name="">
        <color rgba="0.75294 0.75294 0.75294 1"/>
      </material>
    </visual>
    <collision>
      <origin rpy="0 0 0" xyz="0 0 0"/>
      <geometry>
        <mesh filename="package://m_2025642_001_description/meshes/base_link.STL"/>
      </geometry>
    </collision>
  </link>
  <link name="c_303_robot_arm_2_link_1">
    <inertial>
      <origin rpy="0 0 0" xyz="0.27383 -0.0063157 -0.28956"/>
      <mass value="4.7027"/>
      <inertia ixx="0.25522" ixy="0.013056" ixz="-0.34403" iyy="0.85224" iyz="0.0078809" izz="0.63965"/>
    </inertial>
    <visual>
      <origin rpy="0 0 0" xyz="0 0 0"/>
      <geometry>
        <mesh filename="package://m_2025642_001_description/meshes/link_1.STL"/>
      </geometry>
      <material name="">
        <color rgba="0.75294 0.75294 0.75294 1"/>
      </material>
    </visual>
    <collision>
      <origin rpy="0 0 0" xyz="0 0 0"/>
      <geometry>
        <mesh filename="package://m_2025642_001_description/meshes/link_1.STL"/>
      </geometry>
    </collision>
  </link>
  <joint name="c_303_robot_arm_2_joint_1" type="revolute">
    <origin rpy="0 0 0" xyz="0 0 0.57269"/>
    <parent link="c_303_robot_arm_2_base_link"/>
    <child link="c_303_robot_arm_2_link_1"/>
    <axis xyz="0 0 1"/>
    <limit effort="0.1" lower="-1.0" upper="1.0" velocity="0.1"/>
  </joint>
  <link name="c_303_robot_arm_2_link_2">
    <inertial>
      <origin rpy="0 0 0" xyz="-0.075618 0.013344 -0.40578"/>
      <mass value="4.7027"/>
      <inertia ixx="0.25522" ixy="0.013056" ixz="-0.34403" iyy="0.85224" iyz="0.0078809" izz="0.63965"/>
    </inertial>
    <visual>
      <origin rpy="0 0 0" xyz="0 0 0"/>
      <geometry>
        <mesh filename="package://m_2025642_001_description/meshes/link_2.STL"/>
      </geometry>
      <material name="">
        <color rgba="0.75294 0.75294 0.75294 1"/>
      </material>
    </visual>
    <collision>
      <origin rpy="0 0 0" xyz="0 0 0"/>
      <geometry>
        <mesh filename="package://m_2025642_001_description/meshes/link_2.STL"/>
      </geometry>
    </collision>
  </link>
  <joint name="c_303_robot_arm_2_joint_2" type="revolute">
    <origin rpy="0 0 0" xyz="0.34945 -0.019659 0.11622"/>
    <parent link="c_303_robot_arm_2_link_1"/>
    <child link="c_303_robot_arm_2_link_2"/>
    <axis xyz="0 0 1"/>
    <limit effort="0.1" lower="-1.0" upper="1.0" velocity="0.1"/>
  </joint>
  <link name="c_303_robot_arm_2_link_3">
    <inertial>
      <origin rpy="0 0 0" xyz="-0.42562 0.013344 -0.39507"/>
      <mass value="4.7027"/>
      <inertia ixx="0.25522" ixy="0.013056" ixz="-0.34403" iyy="0.85224" iyz="0.0078809" izz="0.63965"/>
    </inertial>
    <visual>
      <origin rpy="0 0 0" xyz="0 0 0"/>
      <geometry>
        <mesh filename="package://m_2025642_001_description/meshes/link_3.STL"/>
      </geometry>
      <material name="">
        <color rgba="0.75294 0.75294 0.75294 1"/>
      </material>
    </visual>
    <collision>
      <origin rpy="0 0 0" xyz="0 0 0"/>
      <geometry>
        <mesh filename="package://m_2025642_001_description/meshes/link_3.STL"/>
      </geometry>
    </collision>
  </link>
  <joint name="c_303_robot_arm_2_joint_3" type="prismatic">
    <origin rpy="0 0 0" xyz="0.35 0 -0.01071"/>
    <parent link="c_303_robot_arm_2_link_2"/>
    <child link="c_303_robot_arm_2_link_3"/>
    <axis xyz="0 0 1"/>
    <limit effort="0.1" lower="-0.1" upper="0.05" velocity="0.1"/>
  </joint>
  <link name="c_303_robot_arm_2_link_4">
    <inertial>
      <origin rpy="0 0 0" xyz="0.018596 0.0019918 0.018216"/>
      <mass value="1.0033"/>
      <inertia ixx="0.00065498" ixy="2.4675E-06" ixz="-1.1852E-05" iyy="0.0040429" iyz="4.0062E-06" izz="0.0045133"/>
    </inertial>
    <visual>
      <origin rpy="0 0 0" xyz="0 0 0"/>
      <geometry>
        <mesh filename="package://m_2025642_001_description/meshes/link_4.STL"/>
      </geometry>
      <material name="">
        <color rgba="0.75294 0.75294 0.75294 1"/>
      </material>
    </visual>
    <collision>
      <origin rpy="0 0 0" xyz="0 0 0"/>
      <geometry>
        <mesh filename="package://m_2025642_001_description/meshes/link_4.STL"/>
      </geometry>
    </collision>
  </link>
  <joint name="c_303_robot_arm_2_joint_4" type="revolute">
    <origin rpy="0 0 0" xyz="0 0.0020727 -0.155"/>
    <parent link="c_303_robot_arm_2_link_3"/>
    <child link="c_303_robot_arm_2_link_4"/>
    <axis xyz="0 0 1"/>
    <limit effort="0.1" lower="-0.2" upper="0.2" velocity="0.1"/>
  </joint>
  <link name="c_303_robot_arm_2_gripper_right_link">
    <inertial>
      <origin rpy="0 0 0" xyz="-0.042744 0.0023468 0.042891"/>
      <mass value="0.43089"/>
      <inertia ixx="0.00044467" ixy="-5.9136E-06" ixz="5.7977E-05" iyy="0.00073715" iyz="-1.5119E-06" izz="0.00087355"/>
    </inertial>
    <visual>
      <origin rpy="0 0 0" xyz="0 0 0"/>
      <geometry>
        <mesh filename="package://m_2025642_001_description/meshes/gripper_right_link.STL"/>
      </geometry>
      <material name="">
        <color rgba="0.75294 0.75294 0.75294 1"/>
      </material>
    </visual>
    <collision>
      <origin rpy="0 0 0" xyz="0 0 0"/>
      <geometry>
        <mesh filename="package://m_2025642_001_description/meshes/gripper_right_link.STL"/>
      </geometry>
    </collision>
  </link>
  <joint name="c_303_robot_arm_2_gripper_right_joint" type="prismatic">
    <origin rpy="0 0 0" xyz="0.19 -0.0020727 0.0014243"/>
    <parent link="c_303_robot_arm_2_link_4"/>
    <child link="c_303_robot_arm_2_gripper_right_link"/>
    <axis xyz="1 0 0"/>
    <limit effort="0.1" lower="0" upper="0.1" velocity="0.1"/>
  </joint>
  <link name="c_303_robot_arm_2_gripper_left_link">
    <inertial>
      <origin rpy="0 0 0" xyz="0.007756 0.0016325 0.025599"/>
      <mass value="0.36755"/>
      <inertia ixx="0.00075935" ixy="1.125E-08" ixz="-2.7795E-05" iyy="0.00045486" iyz="5.4225E-08" izz="0.00079529"/>
    </inertial>
    <visual>
      <origin rpy="0 0 0" xyz="0 0 0"/>
      <geometry>
        <mesh filename="package://m_2025642_001_description/meshes/gripper_left_link.STL"/>
      </geometry>
      <material name="">
        <color rgba="0.75294 0.75294 0.75294 1"/>
      </material>
    </visual>
    <collision>
      <origin rpy="0 0 0" xyz="0 0 0"/>
      <geometry>
        <mesh filename="package://m_2025642_001_description/meshes/gripper_left_link.STL"/>
      </geometry>
    </collision>
  </link>
  <joint name="c_303_robot_arm_2_gripper_left_joint" type="prismatic">
    <origin rpy="0 0 0" xyz="-0.156 -0.0020727 0.0014243"/>
    <parent link="c_303_robot_arm_2_link_4"/>
    <child link="c_303_robot_arm_2_gripper_left_link"/>
    <axis xyz="-1 0 0"/>
    <limit effort="0.1" lower="0" upper="0.06" velocity="0.1"/>
  </joint>
  <link name="c_304_pick_place_system_2_base_link">
    <inertial>
      <origin rpy="0 0 0" xyz="0.58983 0.63355 0.96408"/>
      <mass value="56.671"/>
      <inertia ixx="5.0862" ixy="0.096549" ixz="0.011489" iyy="11.551" iyz="0.00029138" izz="15.131"/>
    </inertial>
    <visual>
      <origin rpy="0 0 0" xyz="0 0 0"/>
      <geometry>
        <mesh filename="package://m_2025643_001_description/meshes/base_link.STL"/>
      </geometry>
      <material name="">
        <color rgba="0.75294 0.75294 0.75294 1"/>
      </material>
    </visual>
    <collision>
      <origin rpy="0 0 0" xyz="0 0 0"/>
      <geometry>
        <mesh filename="package://m_2025643_001_description/meshes/base_link.STL"/>
      </geometry>
    </collision>
  </link>
  <link name="c_304_pick_place_system_2_link_1">
    <inertial>
      <origin rpy="0 0 0" xyz="0.11461 -0.023751 -0.20534"/>
      <mass value="17.887"/>
      <inertia ixx="0.85265" ixy="0.0020243" ixz="0.0034461" iyy="0.42068" iyz="-0.00010302" izz="0.47399"/>
    </inertial>
    <visual>
      <origin rpy="0 0 0" xyz="0 0 0"/>
      <geometry>
        <mesh filename="package://m_2025643_001_description/meshes/link_1.STL"/>
      </geometry>
      <material name="">
        <color rgba="0.75294 0.75294 0.75294 1"/>
      </material>
    </visual>
    <collision>
      <origin rpy="0 0 0" xyz="0 0 0"/>
      <geometry>
        <mesh filename="package://m_2025643_001_description/meshes/link_1.STL"/>
      </geometry>
    </collision>
  </link>
  <joint name="c_304_pick_place_system_2_joint_1" type="prismatic">
    <origin rpy="0 0 0" xyz="-0.37671 0.676 1.2315"/>
    <parent link="c_304_pick_place_system_2_base_link"/>
    <child link="c_304_pick_place_system_2_link_1"/>
    <axis xyz="1 0 0"/>
    <limit effort="0.1" lower="0" upper="1.5" velocity="0.1"/>
  </joint>
  <link name="c_304_pick_place_system_2_link_2">
    <inertial>
      <origin rpy="0 0 0" xyz="0.070659 -0.031425 0.0021627"/>
      <mass value="8.1181"/>
      <inertia ixx="0.43894" ixy="0.0013519" ixz="0.00017093" iyy="0.045982" iyz="-0.0024625" izz="0.45094"/>
    </inertial>
    <visual>
      <origin rpy="0 0 0" xyz="0 0 0"/>
      <geometry>
        <mesh filename="package://m_2025643_001_description/meshes/link_2.STL"/>
      </geometry>
      <material name="">
        <color rgba="0.75294 0.75294 0.75294 1"/>
      </material>
    </visual>
    <collision>
      <origin rpy="0 0 0" xyz="0 0 0"/>
      <geometry>
        <mesh filename="package://m_2025643_001_description/meshes/link_2.STL"/>
      </geometry>
    </collision>
  </link>
  <joint name="c_304_pick_place_system_2_joint_2" type="prismatic">
    <origin rpy="0 0 0" xyz="0.20285 -0.084066 -0.62709"/>
    <parent link="c_304_pick_place_system_2_link_1"/>
    <child link="c_304_pick_place_system_2_link_2"/>
    <axis xyz="0 0 1"/>
    <limit effort="0.1" lower="0" upper="0.5" velocity="0.1"/>
  </joint>
  <link name="c_304_pick_place_system_2_gripper_left_link">
    <inertial>
      <origin rpy="0 0 0" xyz="-0.016946 -0.019226 -0.088431"/>
      <mass value="1.0465"/>
      <inertia ixx="0.0009527" ixy="-0.00010594" ixz="0.00013512" iyy="0.0010535" iyz="0.00011099" izz="0.001289"/>
    </inertial>
    <visual>
      <origin rpy="0 0 0" xyz="0 0 0"/>
      <geometry>
        <mesh filename="package://m_2025643_001_description/meshes/gripper_left_link.STL"/>
      </geometry>
      <material name="">
        <color rgba="0.75294 0.75294 0.75294 1"/>
      </material>
    </visual>
    <collision>
      <origin rpy="0 0 0" xyz="0 0 0"/>
      <geometry>
        <mesh filename="package://m_2025643_001_description/meshes/gripper_left_link.STL"/>
      </geometry>
    </collision>
  </link>
  <joint name="c_304_pick_place_system_2_gripper_left_joint" type="prismatic">
    <origin rpy="0 0 0" xyz="0.286 -0.37124 -0.046329"/>
    <parent link="c_304_pick_place_system_2_link_2"/>
    <child link="c_304_pick_place_system_2_gripper_left_link"/>
    <axis xyz="0 1 0"/>
    <limit effort="0.1" lower="0" upper="0.1" velocity="0.1"/>
  </joint>
  <link name="c_304_pick_place_system_2_finger_left_link">
    <inertial>
      <origin rpy="0 0 0" xyz="0.0044985 0.062888 -0.006434"/>
      <mass value="0.38585"/>
      <inertia ixx="0.00020691" ixy="2.0797E-07" ixz="-4.5948E-07" iyy="0.00034559" iyz="-3.5191E-07" izz="0.00038383"/>
    </inertial>
    <visual>
      <origin rpy="0 0 0" xyz="0 0 0"/>
      <geometry>
        <mesh filename="package://m_2025643_001_description/meshes/finger_left_link.STL"/>
      </geometry>
      <material name="">
        <color rgba="0.75294 0.75294 0.75294 1"/>
      </material>
    </visual>
    <collision>
      <origin rpy="0 0 0" xyz="0 0 0"/>
      <geometry>
        <mesh filename="package://m_2025643_001_description/meshes/finger_left_link.STL"/>
      </geometry>
    </collision>
  </link>
  <joint name="c_304_pick_place_system_2_finger_left_joint" type="revolute">
    <origin rpy="0 0 0" xyz="0 0.047 -0.148"/>
    <parent link="c_304_pick_place_system_2_gripper_left_link"/>
    <child link="c_304_pick_place_system_2_finger_left_link"/>
    <axis xyz="0 1 0"/>
    <limit effort="0.1" lower="-0.5" upper="0.5" velocity="0.1"/>
  </joint>
  <link name="c_308_workpiece_lifter_2_base_link">
    <inertial>
      <origin rpy="0 0 0" xyz="0.23397 0.00029888 0.15629"/>
      <mass value="5.7833"/>
      <inertia ixx="0.029824" ixy="0.0001163" ixz="-2.0315E-05" iyy="0.044642" iyz="3.2398E-05" izz="0.057924"/>
    </inertial>
    <visual>
      <origin rpy="0 0 0" xyz="0 0 0"/>
      <geometry>
        <mesh filename="package://m_2063306_000_description/meshes/base_link.STL"/>
      </geometry>
      <material name="">
        <color rgba="0.75294 0.75294 0.75294 1"/>
      </material>
    </visual>
    <collision>
      <origin rpy="0 0 0" xyz="0 0 0"/>
      <geometry>
        <mesh filename="package://m_2063306_000_description/meshes/base_link.STL"/>
      </geometry>
    </collision>
  </link>
  <link name="c_308_workpiece_lifter_2_link_1">
    <inertial>
      <origin rpy="0 0 0" xyz="-0.0010188 0.00075539 0.25483"/>
      <mass value="4.9135"/>
      <inertia ixx="0.023378" ixy="-0.00023389" ixz="5.6233E-06" iyy="0.026512" iyz="-1.1668E-05" izz="0.044967"/>
    </inertial>
    <visual>
      <origin rpy="0 0 0" xyz="0 0 0"/>
      <geometry>
        <mesh filename="package://m_2063306_000_description/meshes/link_1.STL"/>
      </geometry>
      <material name="">
        <color rgba="0.75294 0.75294 0.75294 1"/>
      </material>
    </visual>
    <collision>
      <origin rpy="0 0 0" xyz="0 0 0"/>
      <geometry>
        <mesh filename="package://m_2063306_000_description/meshes/link_1.STL"/>
      </geometry>
    </collision>
  </link>
  <joint name="c_308_workpiece_lifter_2_joint_1" type="prismatic">
    <origin rpy="0 0 0" xyz="0.2845 0 0.127"/>
    <parent link="c_308_workpiece_lifter_2_base_link"/>
    <child link="c_308_workpiece_lifter_2_link_1"/>
    <axis xyz="0 0 1"/>
    <limit effort="0.1" lower="0" upper="0.1" velocity="0.1"/>
  </joint>
  <link name="c_305_workpiece_holder_2_base_link">
    <inertial>
      <origin rpy="0 0 0" xyz="-0.00033345 0.00023906 0.25293"/>
      <mass value="2.0735"/>
      <inertia ixx="0.0091049" ixy="-7.0561E-07" ixz="-1.5489E-07" iyy="0.0061399" iyz="4.7348E-08" izz="0.012288"/>
    </inertial>
    <visual>
      <origin rpy="0 0 0" xyz="0 0 0"/>
      <geometry>
        <mesh filename="package://m_2154940_001_description/meshes/base_link.STL"/>
      </geometry>
      <material name="">
        <color rgba="0.75294 0.75294 0.75294 1"/>
      </material>
    </visual>
    <collision>
      <origin rpy="0 0 0" xyz="0 0 0"/>
      <geometry>
        <mesh filename="package://m_2154940_001_description/meshes/base_link.STL"/>
      </geometry>
    </collision>
  </link>
  <link name="c_306_height_check_system_2_base_link">
    <inertial>
      <origin rpy="0 0 0" xyz="-0.0079588 0.53745 0.29257"/>
      <mass value="25.945"/>
      <inertia ixx="3.1047" ixy="7.4183E-05" ixz="-0.00021729" iyy="0.061286" iyz="0.0088416" izz="3.1103"/>
    </inertial>
    <visual>
      <origin rpy="0 0 0" xyz="0 0 0"/>
      <geometry>
        <mesh filename="package://m_4730788_001_description/meshes/base_link.STL"/>
      </geometry>
      <material name="">
        <color rgba="0.75294 0.75294 0.75294 1"/>
      </material>
    </visual>
    <collision>
      <origin rpy="0 0 0" xyz="0 0 0"/>
      <geometry>
        <mesh filename="package://m_4730788_001_description/meshes/base_link.STL"/>
      </geometry>
    </collision>
  </link>
  <link name="c_306_height_check_system_2_link_1">
    <inertial>
      <origin rpy="0 0 0" xyz="0.035968 0.27493 0.22182"/>
      <mass value="5.6095"/>
      <inertia ixx="0.069776" ixy="-4.5144E-06" ixz="-0.00039418" iyy="0.068863" iyz="-3.9361E-06" izz="0.0062752"/>
    </inertial>
    <visual>
      <origin rpy="0 0 0" xyz="0 0 0"/>
      <geometry>
        <mesh filename="package://m_4730788_001_description/meshes/link_1.STL"/>
      </geometry>
      <material name="">
        <color rgba="0.75294 0.75294 0.75294 1"/>
      </material>
    </visual>
    <collision>
      <origin rpy="0 0 0" xyz="0 0 0"/>
      <geometry>
        <mesh filename="package://m_4730788_001_description/meshes/link_1.STL"/>
      </geometry>
    </collision>
  </link>
  <joint name="c_306_height_check_system_2_joint_1" type="prismatic">
    <origin rpy="0 0 0" xyz="0 -0.0041461 0.37535"/>
    <parent link="c_306_height_check_system_2_base_link"/>
    <child link="c_306_height_check_system_2_link_1"/>
    <axis xyz="0 1 0"/>
    <limit effort="0.1" lower="0" upper="1.0" velocity="0.1"/>
  </joint>
  <link name="c_306_height_check_system_2_link_2">
    <inertial>
      <origin rpy="0 0 0" xyz="0.1819 1.4438E-05 -0.12956"/>
      <mass value="1.8798"/>
      <inertia ixx="0.0025187" ixy="-1.2207E-05" ixz="8.5334E-07" iyy="0.0027656" iyz="1.0645E-07" izz="0.0012183"/>
    </inertial>
    <visual>
      <origin rpy="0 0 0" xyz="0 0 0"/>
      <geometry>
        <mesh filename="package://m_4730788_001_description/meshes/link_2.STL"/>
      </geometry>
      <material name="">
        <color rgba="0.75294 0.75294 0.75294 1"/>
      </material>
    </visual>
    <collision>
      <origin rpy="0 0 0" xyz="0 0 0"/>
      <geometry>
        <mesh filename="package://m_4730788_001_description/meshes/link_2.STL"/>
      </geometry>
    </collision>
  </link>
  <joint name="c_306_height_check_system_2_joint_2" type="prismatic">
    <origin rpy="0 0 0" xyz="0.074922 0.27494 0.46365"/>
    <parent link="c_306_height_check_system_2_link_1"/>
    <child link="c_306_height_check_system_2_link_2"/>
    <axis xyz="0 0 1"/>
    <limit effort="0.1" lower="-0.2" upper="0.25" velocity="0.1"/>
  </joint>
  <link name="c_307_workpiece_feeder_2_base_link">
    <inertial>
      <origin rpy="0 0 0" xyz="-0.14164 -0.59781 -0.44321"/>
      <mass value="21.523"/>
      <inertia ixx="0.088184" ixy="3.5897E-05" ixz="-1.1803E-05" iyy="2.7101" iyz="-0.0006684" izz="2.6633"/>
    </inertial>
    <visual>
      <origin rpy="0 0 0" xyz="0 0 0"/>
      <geometry>
        <mesh filename="package://m_5326927_001_description/meshes/base_link.STL"/>
      </geometry>
      <material name="">
        <color rgba="0.8549 0.74118 0.91765 1"/>
      </material>
    </visual>
    <collision>
      <origin rpy="0 0 0" xyz="0 0 0"/>
      <geometry>
        <mesh filename="package://m_5326927_001_description/meshes/base_link.STL"/>
      </geometry>
    </collision>
  </link>
  <link name="c_307_workpiece_feeder_2_zone_link">
    <visual>
      <origin rpy="0 0 0" xyz="0 0 0"/>
      <geometry>
        <box size="0.4 0.65 0.1"/>
      </geometry>
    </visual>
    <collision>
      <origin rpy="0 0 0" xyz="0 0 0"/>
      <geometry>
        <box size="0.4 0.65 0.1"/>
      </geometry>
    </collision>
  </link>
  <joint name="c_307_workpiece_feeder_2_joint_1" type="prismatic">
    <origin rpy="0 0 0" xyz="0 0 0.6"/>
    <parent link="c_307_workpiece_feeder_2_base_link"/>
    <child link="c_307_workpiece_feeder_2_zone_link"/>
    <axis xyz="0 1 0"/>
    <limit effort="0.1" lower="0" upper="1.5" velocity="0.1"/>
  </joint>
  <link name="world"/>
  <joint name="c_203_robot_arm_joint" type="fixed">
    <origin rpy="0 0 1.571" xyz="-0.6 0.3 0"/>
    <parent link="world"/>
    <child link="c_203_robot_arm_base_link"/>
  </joint>
  <joint name="c_204_pick_place_system_joint" type="fixed">
    <origin rpy="0 0 0" xyz="0 0 0"/>
    <parent link="world"/>
    <child link="c_204_pick_place_system_base_link"/>
  </joint>
  <joint name="c_205_workpiece_holder_joint" type="fixed">
    <origin rpy="0 0 0" xyz="0.25 0.6 0"/>
    <parent link="world"/>
    <child link="c_205_workpiece_holder_base_link"/>
  </joint>
  <joint name="c_206_height_check_system_joint" type="fixed">
    <origin rpy="0 0 3.142" xyz="0.7 1.2 0"/>
    <parent link="world"/>
    <child link="c_206_height_check_system_base_link"/>
  </joint>
  <joint name="c_207_workpiece_feeder_joint" type="fixed">
    <origin rpy="0 0 0" xyz="1.1 0 0"/>
    <parent link="world"/>
    <child link="c_207_workpiece_feeder_base_link"/>
  </joint>
  <joint name="c_208_workpiece_lifter_joint" type="fixed">
    <origin rpy="0 0 0" xyz="-0.28 0.85 0"/>
    <parent link="c_207_workpiece_feeder_base_link"/>
    <child link="c_208_workpiece_lifter_base_link"/>
  </joint>
  <joint name="c_303_robot_arm_2_joint" type="fixed">
    <origin rpy="0 0 1.571" xyz="-0.6 2.3 0"/>
    <parent link="world"/>
    <child link="c_303_robot_arm_2_base_link"/>
  </joint>
  <joint name="c_304_pick_place_system_2_joint" type="fixed">
    <origin rpy="0 0 0" xyz="0 2 0"/>
    <parent link="world"/>
    <child link="c_304_pick_place_system_2_base_link"/>
  </joint>
  <joint name="c_305_workpiece_holder_2_joint" type="fixed">
    <origin rpy="0 0 0" xyz="0.25 3.6 0"/>
    <parent link="world"/>
    <child link="c_305_workpiece_holder_2_base_link"/>
  </joint>
  <joint name="c_306_height_check_system_2_joint" type="fixed">
    <origin rpy="0 0 3.142" xyz="0.7 3.2 0"/>
    <parent link="world"/>
    <child link="c_306_height_check_system_2_base_link"/>
  </joint>
  <joint name="c_307_workpiece_feeder_2_joint" type="fixed">
    <origin rpy="0 0 0" xyz="1.1 2 0"/>
    <parent link="world"/>
    <child link="c_307_workpiece_feeder_2_base_link"/>
  </joint>
  <joint name="c_308_workpiece_lifter_2_joint" type="fixed">
    <origin rpy="0 0 0" xyz="-0.28 2.85 0"/>
    <parent link="c_307_workpiece_feeder_2_base_link"/>
    <child link="c_308_workpiece_lifter_2_base_link"/>
  </joint>
</robot>
