<?xml version="1.0" ?>
<!-- =================================================================================== -->
<!-- |    This document was autogenerated by xacro from /home/ipa-hsd/projects/denso/ros2_ws/src/component_models/codenser/m_2025643_001/m_2025643_001_description/urdf/m_2025643_001.urdf.xacro | -->
<!-- |    EDITING THIS FILE BY HAND IS NOT RECOMMENDED                                 | -->
<!-- =================================================================================== -->
<!-- This URDF was automatically created by SolidWorks to URDF Exporter! Originally created by Stephen Brawner (brawner@gmail.com) 
     Commit Version: 1.6.1-12-ge40d886  Build Version: 1.6.8301.19567
     For more information, please see http://wiki.ros.org/sw_urdf_exporter -->
<robot name="m_2025643_001">
  <link name="m_2025643_001_base_link">
    <inertial>
      <origin rpy="0 0 0" xyz="0.58983 0.63355 0.96408"/>
      <mass value="56.671"/>
      <inertia ixx="5.0862" ixy="0.096549" ixz="0.011489" iyy="11.551" iyz="0.00029138" izz="15.131"/>
    </inertial>
    <visual>
      <origin rpy="0 0 0" xyz="0 0 0"/>
      <geometry>
        <mesh filename="package://m_2025643_001_description/meshes/base_link.STL"/>
      </geometry>
      <material name="">
        <color rgba="0.75294 0.75294 0.75294 1"/>
      </material>
    </visual>
    <collision>
      <origin rpy="0 0 0" xyz="0 0 0"/>
      <geometry>
        <mesh filename="package://m_2025643_001_description/meshes/base_link.STL"/>
      </geometry>
    </collision>
  </link>
  <link name="m_2025643_001_link_1">
    <inertial>
      <origin rpy="0 0 0" xyz="0.11461 -0.023751 -0.20534"/>
      <mass value="17.887"/>
      <inertia ixx="0.85265" ixy="0.0020243" ixz="0.0034461" iyy="0.42068" iyz="-0.00010302" izz="0.47399"/>
    </inertial>
    <visual>
      <origin rpy="0 0 0" xyz="0 0 0"/>
      <geometry>
        <mesh filename="package://m_2025643_001_description/meshes/link_1.STL"/>
      </geometry>
      <material name="">
        <color rgba="0.75294 0.75294 0.75294 1"/>
      </material>
    </visual>
    <collision>
      <origin rpy="0 0 0" xyz="0 0 0"/>
      <geometry>
        <mesh filename="package://m_2025643_001_description/meshes/link_1.STL"/>
      </geometry>
    </collision>
  </link>
  <joint name="m_2025643_001_joint_1" type="prismatic">
    <origin rpy="0 0 0" xyz="-0.37671 0.676 1.2315"/>
    <parent link="m_2025643_001_base_link"/>
    <child link="m_2025643_001_link_1"/>
    <axis xyz="1 0 0"/>
    <limit effort="0.1" lower="0" upper="1.5" velocity="0.1"/>
  </joint>
  <link name="m_2025643_001_link_2">
    <inertial>
      <origin rpy="0 0 0" xyz="0.070659 -0.031425 0.0021627"/>
      <mass value="8.1181"/>
      <inertia ixx="0.43894" ixy="0.0013519" ixz="0.00017093" iyy="0.045982" iyz="-0.0024625" izz="0.45094"/>
    </inertial>
    <visual>
      <origin rpy="0 0 0" xyz="0 0 0"/>
      <geometry>
        <mesh filename="package://m_2025643_001_description/meshes/link_2.STL"/>
      </geometry>
      <material name="">
        <color rgba="0.75294 0.75294 0.75294 1"/>
      </material>
    </visual>
    <collision>
      <origin rpy="0 0 0" xyz="0 0 0"/>
      <geometry>
        <mesh filename="package://m_2025643_001_description/meshes/link_2.STL"/>
      </geometry>
    </collision>
  </link>
  <joint name="m_2025643_001_joint_2" type="prismatic">
    <origin rpy="0 0 0" xyz="0.20285 -0.084066 -0.62709"/>
    <parent link="m_2025643_001_link_1"/>
    <child link="m_2025643_001_link_2"/>
    <axis xyz="0 0 1"/>
    <limit effort="0.1" lower="0" upper="0.5" velocity="0.1"/>
  </joint>
  <link name="m_2025643_001_gripper_left_link">
    <inertial>
      <origin rpy="0 0 0" xyz="-0.016946 -0.019226 -0.088431"/>
      <mass value="1.0465"/>
      <inertia ixx="0.0009527" ixy="-0.00010594" ixz="0.00013512" iyy="0.0010535" iyz="0.00011099" izz="0.001289"/>
    </inertial>
    <visual>
      <origin rpy="0 0 0" xyz="0 0 0"/>
      <geometry>
        <mesh filename="package://m_2025643_001_description/meshes/gripper_left_link.STL"/>
      </geometry>
      <material name="">
        <color rgba="0.75294 0.75294 0.75294 1"/>
      </material>
    </visual>
    <collision>
      <origin rpy="0 0 0" xyz="0 0 0"/>
      <geometry>
        <mesh filename="package://m_2025643_001_description/meshes/gripper_left_link.STL"/>
      </geometry>
    </collision>
  </link>
  <joint name="m_2025643_001_gripper_left_joint" type="prismatic">
    <origin rpy="0 0 0" xyz="0.286 -0.37124 -0.046329"/>
    <parent link="m_2025643_001_link_2"/>
    <child link="m_2025643_001_gripper_left_link"/>
    <axis xyz="0 1 0"/>
    <limit effort="0.1" lower="0" upper="0.1" velocity="0.1"/>
  </joint>
  <link name="m_2025643_001_finger_left_link">
    <inertial>
      <origin rpy="0 0 0" xyz="0.0044985 0.062888 -0.006434"/>
      <mass value="0.38585"/>
      <inertia ixx="0.00020691" ixy="2.0797E-07" ixz="-4.5948E-07" iyy="0.00034559" iyz="-3.5191E-07" izz="0.00038383"/>
    </inertial>
    <visual>
      <origin rpy="0 0 0" xyz="0 0 0"/>
      <geometry>
        <mesh filename="package://m_2025643_001_description/meshes/finger_left_link.STL"/>
      </geometry>
      <material name="">
        <color rgba="0.75294 0.75294 0.75294 1"/>
      </material>
    </visual>
    <collision>
      <origin rpy="0 0 0" xyz="0 0 0"/>
      <geometry>
        <mesh filename="package://m_2025643_001_description/meshes/finger_left_link.STL"/>
      </geometry>
    </collision>
  </link>
  <joint name="m_2025643_001_finger_left_joint" type="revolute">
    <origin rpy="0 0 0" xyz="0 0.047 -0.148"/>
    <parent link="m_2025643_001_gripper_left_link"/>
    <child link="m_2025643_001_finger_left_link"/>
    <axis xyz="0 1 0"/>
    <limit effort="0.1" lower="-0.5" upper="0.5" velocity="0.1"/>
  </joint>
</robot>
